Workbook

Sheet Assumptions & Sources
B1: ARANYA CARBON — FINANCIAL MODEL (2026)
B2: Community Forest Carbon Credit Platform — India • Realistic, pre-seed / hackathon stage
B3: Legend: BLUE = input you can change • BLACK = formula • YELLOW = key assumption to validate. Change the exchange rate or price once here and the whole model updates.
B5: A. EXCHANGE RATE
B6: Assumption | C6: Value | D6: Unit | E6: Notes | F6: Src
B7: USD → INR exchange rate | C7: 95 | D7: INR per USD | E7: Latest mid-market rate, ~₹95.2 on 15-Jun-2026 (was ₹83 in old model). All USD costs convert via this cell. | F7: [S1]
B9: B. CARBON CREDIT PRICING (per tCO₂e)
B10: Assumption | C10: Value | D10: Unit | E10: Notes | F10: Src
B11: Price — conservative | C11: 8 | D11: USD | E11: Voluntary spot / generic REDD+ avg has been ~$6–$9 in 2025–26. | F11: [S2]
B12: Price — realistic (model base) | C12: 13 | D12: USD | E12: High-integrity Indian community credit w/ co-benefits. Above ~$9 REDD+ spot, below the older $20–$50 premiums that have since fallen. | F12: [S2][S3]
B13: Price — premium / Article 6 | C13: 20 | D13: USD | E13: Co-benefit / Article 6 upside case only. Not used in base projections. | F13: [S3]
B14: Price — realistic (INR) | C14: =C12*C7 | D14: INR/tCO₂e | E14: = realistic USD price × exchange rate.
B16: C. CARBON GENERATION (representative project)
B17: Assumption | C17: Value | D17: Unit | E17: Notes | F17: Src
B18: Forest size — representative project | C18: 200 | D18: hectares | E18: Mid-size community forest used for unit economics.
B19: Sequestration rate | C19: 5 | D19: tCO₂e/ha/yr | E19: Conservative within IPCC tropical-forest range of 3–8; Indian dry-deciduous forests are at the lower end. | F19: [S4]
B20: Gross credits / project / yr | C20: =C18*C19 | D20: tCO₂e | E20: = area × sequestration rate.
B21: Permanence buffer (set-aside) | C21: 0.15 | D21: % | E21: Credits held back as insurance against reversal (fire/loss). Verra norm 10–20%. | F21: [S5]
B22: Saleable credits / project / yr | C22: =C20*(1-C21) | D22: tCO₂e | E22: = gross credits × (1 − buffer).
B24: D. VERIFICATION & REGISTRY COSTS
B25: Assumption | C25: Value | D25: Unit | E25: Notes | F25: Src
B26: Verra registration fee (one-time) | C26: 5000 | D26: USD | E26: Published Verra registration fee. | F26: [S5]
B27: Validation audit (one-time, aggregated) | C27: 12000 | D27: USD | E27: 3rd-party validation, reduced from ~$25–$40K via digital MRV + grouped projects. | F27: [S6]
B28: Annual verification — per project share | C28: 700 | D28: USD | E28: One auditor visit shared across a cluster of ~20 grouped projects (the platform's core efficiency lever). Validate with first audits. | F28: [S6]
B29: Verra annual maintenance | C29: 500 | D29: USD | E29: Published Verra annual account fee. | F29: [S5]
B30: Annual verification + registry pass-through (INR) | C30: =(C28+C29)*C7 | D30: INR/project/yr | E30: = (annual verification + Verra fee) × FX. Deducted from gross before community payout.
B31: One-time field onboarding cost (Aranya-borne) | C31: 50000 | D31: INR | E31: Marginal cash cost per new project (field trip, data, consent). Team salaries are in OPEX.
B32: Reference: industry one-time setup cost | C32: 11300000 | D32: INR | E32: Solo origination for a small community forest historically ~₹1.1–1.2 Cr & 12–18 months (the barrier Aranya removes). | F32: [S6]
B34: E. PLATFORM / REVENUE ASSUMPTIONS
B35: Assumption | C35: Value | D35: Unit | E35: Notes | F35: Src
B36: Aranya commission on credit sales | C36: 0.18 | D36: % | E36: Platform origination fee. Industry range 15–25%; 18% mid-point. | F36: [S3]
B37: Monitoring subscription / project / yr | C37: 100000 | D37: INR | E37: Annual fee for satellite MRV dashboard + audit-ready report.
B38: NGO SaaS subscription | C38: 12000 | D38: INR/month | E38: Per NGO partner for data app + monitoring + document tools.
B39: Enterprise buyer subscription | C39: 200000 | D39: INR/year | E39: Priority credit access + ESG reporting for corporate buyers.
B40: Aranya servicing cost / selling project / yr | C40: 40000 | D40: INR | E40: Field servicing, support and per-project cloud/data allocation.
B41: Mature-project sell-through | C41: 0.9 | D41: % | E41: Share of saleable credits actually sold once a project is established.
B44: SOURCES & REFERENCES
B45: Ref | C45: Source (organisation, year) | E45: URL
B46: [S1] | C46: USD/INR exchange rate — Wise / YCharts mid-market (15-Jun-2026): ~₹95.2 (1-yr ago ~₹85.6) | E46: https://wise.com/in/currency-converter/usd-to-inr-rate/history
B47: [S2] | C47: Carbon Credit Prices Today 2026 — voluntary spot avg ~$6; REDD+ ~$9/tonne | E47: https://carboncredits.com/carbon-prices-today/
...

Sheet CAPEX & OPEX
B1: CAPEX & OPEX — Aranya Carbon (Company Costs)
B2: What it costs to build and run the company. All figures in INR. Per-project external verification is shown in Sheet 3 (pass-through).
B4: CAPEX — ONE-TIME STARTUP COSTS
B5: Item | C5: Cost (INR) | D5: Cost (USD) | E5: Notes
B6: Company incorporation, trademark & compliance | C6: 75000 | D6: =C6/'Assumptions & Sources'!$C$7 | E6: One-time legal/registration setup.
B7: Legal opinions — carbon rights / FRA / contracts | C7: 300000 | D7: =C7/'Assumptions & Sources'!$C$7 | E7: Clarify community carbon ownership; buyer & panchayat agreements.
B8: Platform / MVP build (beyond hackathon prototype) | C8: 1000000 | D8: =C8/'Assumptions & Sources'!$C$7 | E8: Production web app, marketplace, MRV dashboard.
B9: Field equipment (tablets, GPS, basic drone) | C9: 250000 | D9: =C9/'Assumptions & Sources'!$C$7 | E9: Boundary mapping & inventory kit for field team.
B10: Registry / developer account + first methodology | C10: 200000 | D10: =C10/'Assumptions & Sources'!$C$7 | E10: Verra developer account setup & methodology onboarding.
B11: Branding, website & launch marketing | C11: 150000 | D11: =C11/'Assumptions & Sources'!$C$7 | E11: Identity, site, pilot outreach collateral.
B12: Office setup & deposits | C12: 200000 | D12: =C12/'Assumptions & Sources'!$C$7 | E12: Co-working deposit, furniture, basic infra.
B13: Contingency (10%) | C13: =SUM(C6:C12)*0.1 | D13: =C13/'Assumptions & Sources'!$C$7 | E13: Standard buffer on a one-time budget.
B14: TOTAL CAPEX (one-time) | C14: =SUM(C6:C12)+C13 | D14: =C14/'Assumptions & Sources'!$C$7
B16: OPEX — MONTHLY OPERATING COSTS (Year 1 baseline)
B17: Item | C17: Monthly (INR) | D17: Annual (INR) | E17: Notes
B18: Core team salaries (3 × tech/ops, lean) | C18: 135000 | D18: =C18*12 | E18: Founders on minimal pre-seed stipends; lean build team.
B19: Field officers (2 × community onboarding) | C19: 50000 | D19: =C19*12 | E19: On-ground panchayat onboarding & data collection.
B20: Cloud, data & APIs (hosting, GEE, Mapbox, AI) | C20: 25000 | D20: =C20*12 | E20: Vercel/Neon hosting, Earth Engine, maps, Gemini, payments.
B21: Field operations (travel, fuel, per-diem) | C21: 40000 | D21: =C21*12 | E21: Site visits across pilot districts.
B22: Sales & marketing | C22: 20000 | D22: =C22*12 | E22: Buyer outreach, NGO partnerships, content.
B23: Office / co-working / utilities | C23: 20000 | D23: =C23*12 | E23: Workspace, internet, electricity.
B24: Legal & accounting retainer | C24: 15000 | D24: =C24*12 | E24: Ongoing compliance, contracts, bookkeeping.
B25: Software, tools & misc subscriptions | C25: 10000 | D25: =C25*12 | E25: Dev tools, SaaS, communications.
B26: Contingency / buffer | C26: 15000 | D26: =C26*12 | E26: Unbudgeted month-to-month costs.
B27: TOTAL OPEX | C27: =SUM(C18:C26) | D27: =SUM(D18:D26) | E27: Monthly burn × 12 = Year-1 annual OPEX.
B29: Year-1 cash requirement (CAPEX + annual OPEX): | C29: ='CAPEX & OPEX'!$C$14+'CAPEX & OPEX'!$D$27 | E29: Indicative pre-seed ask (before revenue ramp). OPEX grows with headcount in Y2–Y3 (see Sheet 3).

Sheet Revenue Model & Projections
B1: REVENUE MODEL & PROJECTIONS
B2: Realistic base case. Four revenue streams, per-project unit economics, and a conservative 3-year ramp.
B4: REVENUE STREAMS
B5: Stream | C5: Basis | D5: Rate / Fee | E5: Notes
B6: 1. Credit sale commission (primary) | C6: % of gross credit sales | D6: ='Assumptions & Sources'!$C$36 | E6: Earned on every tonne sold via the marketplace.
B7: 2. Monitoring subscription | C7: Per project / year | D7: ='Assumptions & Sources'!$C$37 | E7: Satellite MRV dashboard + annual report.
B8: 3. NGO SaaS subscription | C8: Per NGO / month | D8: ='Assumptions & Sources'!$C$38 | E8: Platform access for partner NGOs.
B9: 4. Enterprise buyer subscription | C9: Per buyer / year | D9: ='Assumptions & Sources'!$C$39 | E9: Priority access + ESG reporting.
B11: UNIT ECONOMICS — PER PROJECT (mature, annual)
B12: Line item | C12: Value | D12: % of gross | E12: Notes
B13: Saleable credits / yr | C13: ='Assumptions & Sources'!$C$22 | E13: From assumptions (after buffer).
B14: Credits sold (mature sell-through) | C14: =C13*'Assumptions & Sources'!$C$41 | E14: = saleable × sell-through.
B15: Price per credit | C15: ='Assumptions & Sources'!$C$14 | E15: Realistic price × FX.
B16: Gross credit sales | C16: =C14*C15 | E16: = credits sold × price.
B17: Aranya commission (18%) | C17: =C16*'Assumptions & Sources'!$C$36 | D17: =C17/$C$16 | E17: Primary revenue.
B18: Monitoring subscription | C18: ='Assumptions & Sources'!$C$37 | D18: =C18/$C$16 | E18: Flat annual fee.
B19: = Aranya revenue / project | C19: =C17+C18 | D19: =C19/$C$16 | E19: Commission + monitoring.
B20: Less: verification + registry (pass-through) | C20: =-'Assumptions & Sources'!$C$30 | D20: =C20/$C$16 | E20: Paid to auditor/Verra; not Aranya margin.
B21: Less: Aranya commission | C21: =-C17 | D21: =C21/$C$16 | E21: Deducted from gross.
B22: = Community payout | C22: =C16+C20+C21 | D22: =C22/$C$16 | E22: Residual to the panchayat (target 70–82% at scale).
B23: Aranya servicing cost / project | C23: =-'Assumptions & Sources'!$C$40 | D23: =C23/$C$16 | E23: Field servicing + cloud allocation.
B24: = Aranya contribution / project / yr | C24: =C19+C23 | D24: =C24/$C$16 | E24: Revenue minus direct servicing cost.
B26: 3-YEAR PROJECTION (REALISTIC RAMP)
B27: Metric | C27: Year 1 | D27: Year 2 | E27: Year 3 | F27: Notes / assumption
B28: Projects onboarded (cumulative) | C28: 8 | D28: 20 | E28: 45 | F28: Conservative ramp; ~1 onboarding/month rising to ~2/month.
B29: Credit-generating projects (selling) | C29: 2 | D29: 10 | E29: 32 | F29: Lags onboarding — registration/issuance takes ~9–18 months.
B30: Sell-through this year | C30: 0.4 | D30: 0.75 | E30: 0.85 | F30: Share of saleable credits sold (ramps as buyer base matures).
B31: NGO SaaS partners | C31: 2 | D31: 5 | E31: 14 | F31: Partner NGOs paying monthly SaaS.
B32: NGO SaaS months billed | C32: 6 | D32: 12 | E32: 12 | F32: Part-year in Y1.
B33: Enterprise buyer subscribers | C33: 1 | D33: 3 | E33: 7 | F33: Corporates on paid subscription.
B34: Operating expenses (OPEX) | C34: ='CAPEX & OPEX'!$D$27 | D34: 5500000 | E34: 8500000 | F34: Y1 from Sheet 2; grows with headcount in Y2–Y3.
B36: Credit commission revenue | C36: =C29*'Assumptions & Sources'!$C$22*C30*'Assumptions & Sources'!$C$14*'Assumptions & Sources'!$C$36 | D36: =D29*'Assumptions & Sources'!$C$22*D30*'Assumptions & Sources'!$C$14*'Assumptions & Sources'!$C$36 | E36: =E29*'Assumptions & Sources'!$C$22*E30*'Assumptions & Sources'!$C$14*'Assumptions & Sources'!$C$36 | F36: = selling × saleable × sell-through × price × 18%.
B37: Monitoring subscription revenue | C37: =C29*'Assumptions & Sources'!$C$37 | D37: =D29*'Assumptions & Sources'!$C$37 | E37: =E29*'Assumptions & Sources'!$C$37 | F37: = selling projects × annual fee.
B38: NGO SaaS revenue | C38: =C31*'Assumptions & Sources'!$C$38*C32 | D38: =D31*'Assumptions & Sources'!$C$38*D32 | E38: =E31*'Assumptions & Sources'!$C$38*E32 | F38: = partners × monthly fee × months.
B39: Enterprise buyer revenue | C39: =C33*'Assumptions & Sources'!$C$39 | D39: =D33*'Assumptions & Sources'!$C$39 | E39: =E33*'Assumptions & Sources'!$C$39 | F39: = subscribers × annual fee.
B40: TOTAL REVENUE | C40: =SUM(C36,C37,C38,C39) | D40: =SUM(D36,D37,D38,D39) | E40: =SUM(E36,E37,E38,E39) | F40: Sum of the four streams.
B42: Onboarding cost (new projects) | C42: =C28*'Assumptions & Sources'!$C$31 | D42: =(D28-C28)*'Assumptions & Sources'!$C$31 | E42: =(E28-D28)*'Assumptions & Sources'!$C$31 | F42: = new projects this year × onboarding cost.
B43: Project servicing cost | C43: =C29*'Assumptions & Sources'!$C$40 | D43: =D29*'Assumptions & Sources'!$C$40 | E43: =E29*'Assumptions & Sources'!$C$40 | F43: = selling projects × servicing cost.
B44: Operating expenses (OPEX) | C44: =C34 | D44: =D34 | E44: =E34 | F44: From operating inputs above.
B45: CAPEX (one-time, Year 1) | C45: ='CAPEX & OPEX'!$C$14 | D45: 0 | E45: 0 | F45: One-time company build (Sheet 2).
...
